{
  "timestamp": "2025-06-17T01:36:32.241346",
  "total_testes": 5,
  "sucessos": 0,
  "falhas": 5,
  "detalhes": [
    {
      "teste": "Health",
      "status": "ERRO",
      "erro": "HTTPConnectionPool(host='localhost', port=8000): Max retries exceeded with url: /health (Caused by NewConnectionError('<urllib3.connection.HTTPConnection object at 0x7f91052ec500>: Failed to establish a new connection: [Errno 111] Connection refused'))"
    },
    {
      "teste": "Test Root",
      "status": "ERRO",
      "erro": "HTTPConnectionPool(host='localhost', port=8000): Max retries exceeded with url: /api/v1/test/ (Caused by NewConnectionError('<urllib3.connection.HTTPConnection object at 0x7f9105f25cd0>: Failed to establish a new connection: [Errno 111] Connection refused'))"
    },
    {
      "teste": "Listar Clientes",
      "status": "ERRO",
      "erro": "HTTPConnectionPool(host='localhost', port=8000): Max retries exceeded with url: /api/v1/test/clientes?loja_id=test (Caused by NewConnectionError('<urllib3.connection.HTTPConnection object at 0x7f91050bfec0>: Failed to establish a new connection: [Errno 111] Connection refused'))"
    },
    {
      "teste": "Dados Iniciais",
      "status": "ERRO",
      "erro": "HTTPConnectionPool(host='localhost', port=8000): Max retries exceeded with url: /api/v1/test/dados-iniciais (Caused by NewConnectionError('<urllib3.connection.HTTPConnection object at 0x7f91050f8620>: Failed to establish a new connection: [Errno 111] Connection refused'))"
    },
    {
      "teste": "CORS",
      "status": "ERRO",
      "erro": "HTTPConnectionPool(host='localhost', port=8000): Max retries exceeded with url: /api/v1/test/clientes (Caused by NewConnectionError('<urllib3.connection.HTTPConnection object at 0x7f91050f8d70>: Failed to establish a new connection: [Errno 111] Connection refused'))"
    }
  ]
}